2018-02-22 00:32:15,468 ERROR: Exception on /post/3 [GET] [in /usr/local/lib/python2.7/dist-packages/flask/app.py:1560]
Traceback (most recent call last):
  File "/usr/local/lib/python2.7/dist-packages/flask/app.py", line 1982, in wsgi_app
    response = self.full_dispatch_request()
  File "/usr/local/lib/python2.7/dist-packages/flask/app.py", line 1614, in full_dispatch_request
    rv = self.handle_user_exception(e)
  File "/usr/local/lib/python2.7/dist-packages/flask/app.py", line 1517, in handle_user_exception
    reraise(exc_type, exc_value, tb)
  File "/usr/local/lib/python2.7/dist-packages/flask/app.py", line 1612, in full_dispatch_request
    rv = self.dispatch_request()
  File "/usr/local/lib/python2.7/dist-packages/flask/app.py", line 1598, in dispatch_request
    return self.view_functions[rule.endpoint](**req.view_args)
  File "/usr/local/lib/python2.7/dist-packages/flask_login/utils.py", line 261, in decorated_view
    return func(*args, **kwargs)
  File "/home/broccoli/161220049_web_programming/blog/app/routes.py", line 109, in post
    return render_template('_post.html', posts=[post], form=form, comments=comments,pagination=pagination)
UnboundLocalError: local variable 'comments' referenced before assignment
2018-02-22 00:35:15,296 INFO: Blog startup [in /home/broccoli/161220049_web_programming/blog/app/__init__.py:44]
2018-02-22 00:35:26,275 ERROR: Exception on /post/3 [GET] [in /usr/local/lib/python2.7/dist-packages/flask/app.py:1560]
Traceback (most recent call last):
  File "/usr/local/lib/python2.7/dist-packages/flask/app.py", line 1982, in wsgi_app
    response = self.full_dispatch_request()
  File "/usr/local/lib/python2.7/dist-packages/flask/app.py", line 1614, in full_dispatch_request
    rv = self.handle_user_exception(e)
  File "/usr/local/lib/python2.7/dist-packages/flask/app.py", line 1517, in handle_user_exception
    reraise(exc_type, exc_value, tb)
  File "/usr/local/lib/python2.7/dist-packages/flask/app.py", line 1612, in full_dispatch_request
    rv = self.dispatch_request()
  File "/usr/local/lib/python2.7/dist-packages/flask/app.py", line 1598, in dispatch_request
    return self.view_functions[rule.endpoint](**req.view_args)
  File "/usr/local/lib/python2.7/dist-packages/flask_login/utils.py", line 261, in decorated_view
    return func(*args, **kwargs)
  File "/home/broccoli/161220049_web_programming/blog/app/routes.py", line 109, in post
    return render_template('_post.html', posts=[post], form=form, comments=comment,pagination=pagination)
UnboundLocalError: local variable 'comment' referenced before assignment
2018-02-22 00:41:41,271 INFO: Blog startup [in /home/broccoli/161220049_web_programming/blog/app/__init__.py:44]
2018-02-22 00:42:00,342 ERROR: Exception on /post/3 [GET] [in /usr/local/lib/python2.7/dist-packages/flask/app.py:1560]
Traceback (most recent call last):
  File "/usr/local/lib/python2.7/dist-packages/flask/app.py", line 1982, in wsgi_app
    response = self.full_dispatch_request()
  File "/usr/local/lib/python2.7/dist-packages/flask/app.py", line 1614, in full_dispatch_request
    rv = self.handle_user_exception(e)
  File "/usr/local/lib/python2.7/dist-packages/flask/app.py", line 1517, in handle_user_exception
    reraise(exc_type, exc_value, tb)
  File "/usr/local/lib/python2.7/dist-packages/flask/app.py", line 1612, in full_dispatch_request
    rv = self.dispatch_request()
  File "/usr/local/lib/python2.7/dist-packages/flask/app.py", line 1598, in dispatch_request
    return self.view_functions[rule.endpoint](**req.view_args)
  File "/usr/local/lib/python2.7/dist-packages/flask_login/utils.py", line 261, in decorated_view
    return func(*args, **kwargs)
  File "/home/broccoli/161220049_web_programming/blog/app/routes.py", line 104, in post
    comments = post.comments()
TypeError: 'AppenderBaseQuery' object is not callable
2018-02-22 00:50:00,867 INFO: Blog startup [in /home/broccoli/161220049_web_programming/blog/app/__init__.py:44]
2018-02-22 00:50:06,187 ERROR: Exception on /post/3 [GET] [in /usr/local/lib/python2.7/dist-packages/flask/app.py:1560]
Traceback (most recent call last):
  File "/usr/local/lib/python2.7/dist-packages/flask/app.py", line 1982, in wsgi_app
    response = self.full_dispatch_request()
  File "/usr/local/lib/python2.7/dist-packages/flask/app.py", line 1614, in full_dispatch_request
    rv = self.handle_user_exception(e)
  File "/usr/local/lib/python2.7/dist-packages/flask/app.py", line 1517, in handle_user_exception
    reraise(exc_type, exc_value, tb)
  File "/usr/local/lib/python2.7/dist-packages/flask/app.py", line 1612, in full_dispatch_request
    rv = self.dispatch_request()
  File "/usr/local/lib/python2.7/dist-packages/flask/app.py", line 1598, in dispatch_request
    return self.view_functions[rule.endpoint](**req.view_args)
  File "/usr/local/lib/python2.7/dist-packages/flask_login/utils.py", line 261, in decorated_view
    return func(*args, **kwargs)
  File "/home/broccoli/161220049_web_programming/blog/app/routes.py", line 105, in post
    comments = post.comments().paginate(page, app.config['COMMENTS_PER_PAGE'], False)
TypeError: 'AppenderBaseQuery' object is not callable
2018-02-22 00:53:27,355 INFO: Blog startup [in /home/broccoli/161220049_web_programming/blog/app/__init__.py:44]
2018-02-22 00:53:30,144 ERROR: Exception on /post/3 [GET] [in /usr/local/lib/python2.7/dist-packages/flask/app.py:1560]
Traceback (most recent call last):
  File "/usr/local/lib/python2.7/dist-packages/flask/app.py", line 1982, in wsgi_app
    response = self.full_dispatch_request()
  File "/usr/local/lib/python2.7/dist-packages/flask/app.py", line 1614, in full_dispatch_request
    rv = self.handle_user_exception(e)
  File "/usr/local/lib/python2.7/dist-packages/flask/app.py", line 1517, in handle_user_exception
    reraise(exc_type, exc_value, tb)
  File "/usr/local/lib/python2.7/dist-packages/flask/app.py", line 1612, in full_dispatch_request
    rv = self.dispatch_request()
  File "/usr/local/lib/python2.7/dist-packages/flask/app.py", line 1598, in dispatch_request
    return self.view_functions[rule.endpoint](**req.view_args)
  File "/usr/local/lib/python2.7/dist-packages/flask_login/utils.py", line 261, in decorated_view
    return func(*args, **kwargs)
  File "/home/broccoli/161220049_web_programming/blog/app/routes.py", line 105, in post
    comments = post.comments.query.order_by(Comment.timestamp.desc()).paginate(page, app.config['COMMENTS_PER_PAGE'], false)
AttributeError: 'AppenderBaseQuery' object has no attribute 'query'
2018-02-22 01:00:13,528 INFO: Blog startup [in /home/broccoli/161220049_web_programming/blog/app/__init__.py:44]
2018-02-22 01:00:15,734 ERROR: Exception on /post/3 [GET] [in /usr/local/lib/python2.7/dist-packages/flask/app.py:1560]
Traceback (most recent call last):
  File "/usr/local/lib/python2.7/dist-packages/flask/app.py", line 1982, in wsgi_app
    response = self.full_dispatch_request()
  File "/usr/local/lib/python2.7/dist-packages/flask/app.py", line 1614, in full_dispatch_request
    rv = self.handle_user_exception(e)
  File "/usr/local/lib/python2.7/dist-packages/flask/app.py", line 1517, in handle_user_exception
    reraise(exc_type, exc_value, tb)
  File "/usr/local/lib/python2.7/dist-packages/flask/app.py", line 1612, in full_dispatch_request
    rv = self.dispatch_request()
  File "/usr/local/lib/python2.7/dist-packages/flask/app.py", line 1598, in dispatch_request
    return self.view_functions[rule.endpoint](**req.view_args)
  File "/usr/local/lib/python2.7/dist-packages/flask_login/utils.py", line 261, in decorated_view
    return func(*args, **kwargs)
  File "/home/broccoli/161220049_web_programming/blog/app/routes.py", line 105, in post
    comments = post.comments.query.order_by(Comment.timestamp.desc()).paginate(page, app.config['COMMENTS_PER_PAGE'], false)
AttributeError: 'function' object has no attribute 'query'
2018-02-22 01:01:26,610 INFO: Blog startup [in /home/broccoli/161220049_web_programming/blog/app/__init__.py:44]
2018-02-22 01:01:28,635 ERROR: Exception on /post/3 [GET] [in /usr/local/lib/python2.7/dist-packages/flask/app.py:1560]
Traceback (most recent call last):
  File "/usr/local/lib/python2.7/dist-packages/flask/app.py", line 1982, in wsgi_app
    response = self.full_dispatch_request()
  File "/usr/local/lib/python2.7/dist-packages/flask/app.py", line 1614, in full_dispatch_request
    rv = self.handle_user_exception(e)
  File "/usr/local/lib/python2.7/dist-packages/flask/app.py", line 1517, in handle_user_exception
    reraise(exc_type, exc_value, tb)
  File "/usr/local/lib/python2.7/dist-packages/flask/app.py", line 1612, in full_dispatch_request
    rv = self.dispatch_request()
  File "/usr/local/lib/python2.7/dist-packages/flask/app.py", line 1598, in dispatch_request
    return self.view_functions[rule.endpoint](**req.view_args)
  File "/usr/local/lib/python2.7/dist-packages/flask_login/utils.py", line 261, in decorated_view
    return func(*args, **kwargs)
  File "/home/broccoli/161220049_web_programming/blog/app/routes.py", line 105, in post
    comments = post.comments().query.order_by(Comment.timestamp.desc()).paginate(page, app.config['COMMENTS_PER_PAGE'], false)
  File "/home/broccoli/161220049_web_programming/blog/app/models.py", line 93, in comments
    comment = Comment.query.filter_by(post=self).all()
  File "/usr/local/lib/python2.7/dist-packages/sqlalchemy/orm/query.py", line 1585, in filter_by
    for key, value in kwargs.items()]
  File "/usr/local/lib/python2.7/dist-packages/sqlalchemy/orm/base.py", line 383, in _entity_descriptor
    (description, key)
InvalidRequestError: Entity '<class 'app.models.Comment'>' has no property 'post'
2018-02-22 01:02:24,686 INFO: Blog startup [in /home/broccoli/161220049_web_programming/blog/app/__init__.py:44]
