2018-02-22 14:02:20,059 ERROR: Exception on /upload_file [POST] [in /usr/local/lib/python2.7/dist-packages/flask/app.py:1560]
Traceback (most recent call last):
  File "/usr/local/lib/python2.7/dist-packages/flask/app.py", line 1982, in wsgi_app
    response = self.full_dispatch_request()
  File "/usr/local/lib/python2.7/dist-packages/flask/app.py", line 1614, in full_dispatch_request
    rv = self.handle_user_exception(e)
  File "/usr/local/lib/python2.7/dist-packages/flask/app.py", line 1517, in handle_user_exception
    reraise(exc_type, exc_value, tb)
  File "/usr/local/lib/python2.7/dist-packages/flask/app.py", line 1612, in full_dispatch_request
    rv = self.dispatch_request()
  File "/usr/local/lib/python2.7/dist-packages/flask/app.py", line 1598, in dispatch_request
    return self.view_functions[rule.endpoint](**req.view_args)
  File "/usr/local/lib/python2.7/dist-packages/flask_login/utils.py", line 261, in decorated_view
    return func(*args, **kwargs)
  File "/home/broccoli/161220049_web_programming/blog/app/routes.py", line 224, in upload_file
    file.save(basedir, os.path.join(app.config['UPLOAD_FOLDER'], filename))
  File "/usr/local/lib/python2.7/dist-packages/werkzeug/datastructures.py", line 2725, in save
    dst = open(dst, 'wb')
IOError: [Errno 21] Is a directory: '/home/broccoli/161220049_web_programming/blog/app'
2018-02-22 14:08:25,728 INFO: Blog startup [in /home/broccoli/161220049_web_programming/blog/app/__init__.py:44]
2018-02-22 14:08:44,883 ERROR: Exception on /upload_file [POST] [in /usr/local/lib/python2.7/dist-packages/flask/app.py:1560]
Traceback (most recent call last):
  File "/usr/local/lib/python2.7/dist-packages/flask/app.py", line 1982, in wsgi_app
    response = self.full_dispatch_request()
  File "/usr/local/lib/python2.7/dist-packages/flask/app.py", line 1614, in full_dispatch_request
    rv = self.handle_user_exception(e)
  File "/usr/local/lib/python2.7/dist-packages/flask/app.py", line 1517, in handle_user_exception
    reraise(exc_type, exc_value, tb)
  File "/usr/local/lib/python2.7/dist-packages/flask/app.py", line 1612, in full_dispatch_request
    rv = self.dispatch_request()
  File "/usr/local/lib/python2.7/dist-packages/flask/app.py", line 1598, in dispatch_request
    return self.view_functions[rule.endpoint](**req.view_args)
  File "/usr/local/lib/python2.7/dist-packages/flask_login/utils.py", line 261, in decorated_view
    return func(*args, **kwargs)
  File "/home/broccoli/161220049_web_programming/blog/app/routes.py", line 224, in upload_file
    file.save(basedir, os.path.join(app.config['UPLOAD_FOLDER'], filename))
  File "/usr/local/lib/python2.7/dist-packages/werkzeug/datastructures.py", line 2725, in save
    dst = open(dst, 'wb')
IOError: [Errno 21] Is a directory: '/home/broccoli/161220049_web_programming/blog/app'
2018-02-22 14:10:15,663 INFO: Blog startup [in /home/broccoli/161220049_web_programming/blog/app/__init__.py:44]
2018-02-22 14:10:32,843 ERROR: Exception on /upload_file [POST] [in /usr/local/lib/python2.7/dist-packages/flask/app.py:1560]
Traceback (most recent call last):
  File "/usr/local/lib/python2.7/dist-packages/flask/app.py", line 1982, in wsgi_app
    response = self.full_dispatch_request()
  File "/usr/local/lib/python2.7/dist-packages/flask/app.py", line 1614, in full_dispatch_request
    rv = self.handle_user_exception(e)
  File "/usr/local/lib/python2.7/dist-packages/flask/app.py", line 1517, in handle_user_exception
    reraise(exc_type, exc_value, tb)
  File "/usr/local/lib/python2.7/dist-packages/flask/app.py", line 1612, in full_dispatch_request
    rv = self.dispatch_request()
  File "/usr/local/lib/python2.7/dist-packages/flask/app.py", line 1598, in dispatch_request
    return self.view_functions[rule.endpoint](**req.view_args)
  File "/usr/local/lib/python2.7/dist-packages/flask_login/utils.py", line 261, in decorated_view
    return func(*args, **kwargs)
  File "/home/broccoli/161220049_web_programming/blog/app/routes.py", line 223, in upload_file
    file.save(os.path.join(app.config['UPLOAD_FOLDER'], filename))
  File "/usr/local/lib/python2.7/dist-packages/werkzeug/datastructures.py", line 2725, in save
    dst = open(dst, 'wb')
IOError: [Errno 2] No such file or directory: '/home/161220049_web_programming/blog/app/upload/air1.jpg'
2018-02-22 14:16:23,530 INFO: Blog startup [in /home/broccoli/161220049_web_programming/blog/app/__init__.py:44]
2018-02-22 14:16:40,628 ERROR: Exception on /upload_file [POST] [in /usr/local/lib/python2.7/dist-packages/flask/app.py:1560]
Traceback (most recent call last):
  File "/usr/local/lib/python2.7/dist-packages/flask/app.py", line 1982, in wsgi_app
    response = self.full_dispatch_request()
  File "/usr/local/lib/python2.7/dist-packages/flask/app.py", line 1614, in full_dispatch_request
    rv = self.handle_user_exception(e)
  File "/usr/local/lib/python2.7/dist-packages/flask/app.py", line 1517, in handle_user_exception
    reraise(exc_type, exc_value, tb)
  File "/usr/local/lib/python2.7/dist-packages/flask/app.py", line 1612, in full_dispatch_request
    rv = self.dispatch_request()
  File "/usr/local/lib/python2.7/dist-packages/flask/app.py", line 1598, in dispatch_request
    return self.view_functions[rule.endpoint](**req.view_args)
  File "/usr/local/lib/python2.7/dist-packages/flask_login/utils.py", line 261, in decorated_view
    return func(*args, **kwargs)
  File "/home/broccoli/161220049_web_programming/blog/app/routes.py", line 223, in upload_file
    file.save(os.path.join(os.path.dirname(realpath(__file__)), app.config['UPLOAD_FOLDER'], filename))
NameError: global name 'realpath' is not defined
2018-02-22 14:17:27,435 INFO: Blog startup [in /home/broccoli/161220049_web_programming/blog/app/__init__.py:44]
2018-02-22 14:17:40,990 ERROR: Exception on /upload_file [POST] [in /usr/local/lib/python2.7/dist-packages/flask/app.py:1560]
Traceback (most recent call last):
  File "/usr/local/lib/python2.7/dist-packages/flask/app.py", line 1982, in wsgi_app
    response = self.full_dispatch_request()
  File "/usr/local/lib/python2.7/dist-packages/flask/app.py", line 1614, in full_dispatch_request
    rv = self.handle_user_exception(e)
  File "/usr/local/lib/python2.7/dist-packages/flask/app.py", line 1517, in handle_user_exception
    reraise(exc_type, exc_value, tb)
  File "/usr/local/lib/python2.7/dist-packages/flask/app.py", line 1612, in full_dispatch_request
    rv = self.dispatch_request()
  File "/usr/local/lib/python2.7/dist-packages/flask/app.py", line 1598, in dispatch_request
    return self.view_functions[rule.endpoint](**req.view_args)
  File "/usr/local/lib/python2.7/dist-packages/flask_login/utils.py", line 261, in decorated_view
    return func(*args, **kwargs)
  File "/home/broccoli/161220049_web_programming/blog/app/routes.py", line 224, in upload_file
    return redirect(url_for('uploaded_file', filename=filename))
  File "/usr/local/lib/python2.7/dist-packages/flask/helpers.py", line 333, in url_for
    return appctx.app.handle_url_build_error(error, endpoint, values)
  File "/usr/local/lib/python2.7/dist-packages/flask/app.py", line 1805, in handle_url_build_error
    reraise(exc_type, exc_value, tb)
  File "/usr/local/lib/python2.7/dist-packages/flask/helpers.py", line 323, in url_for
    force_external=external)
  File "/usr/local/lib/python2.7/dist-packages/werkzeug/routing.py", line 1776, in build
    raise BuildError(endpoint, values, method, self)
BuildError: Could not build url for endpoint 'uploaded_file' with values ['filename']. Did you forget to specify values ['username']?
2018-02-22 14:18:33,564 INFO: Blog startup [in /home/broccoli/161220049_web_programming/blog/app/__init__.py:44]
2018-02-22 14:21:20,208 INFO: Blog startup [in /home/broccoli/161220049_web_programming/blog/app/__init__.py:44]
2018-02-22 14:22:21,195 INFO: Blog startup [in /home/broccoli/161220049_web_programming/blog/app/__init__.py:44]
2018-02-22 14:22:54,976 ERROR: Exception on /upload_file [POST] [in /usr/local/lib/python2.7/dist-packages/flask/app.py:1560]
Traceback (most recent call last):
  File "/usr/local/lib/python2.7/dist-packages/flask/app.py", line 1982, in wsgi_app
    response = self.full_dispatch_request()
  File "/usr/local/lib/python2.7/dist-packages/flask/app.py", line 1614, in full_dispatch_request
    rv = self.handle_user_exception(e)
  File "/usr/local/lib/python2.7/dist-packages/flask/app.py", line 1517, in handle_user_exception
    reraise(exc_type, exc_value, tb)
  File "/usr/local/lib/python2.7/dist-packages/flask/app.py", line 1612, in full_dispatch_request
    rv = self.dispatch_request()
  File "/usr/local/lib/python2.7/dist-packages/flask/app.py", line 1598, in dispatch_request
    return self.view_functions[rule.endpoint](**req.view_args)
  File "/usr/local/lib/python2.7/dist-packages/flask_login/utils.py", line 261, in decorated_view
    return func(*args, **kwargs)
  File "/home/broccoli/161220049_web_programming/blog/app/routes.py", line 223, in upload_file
    file.save(os.path.join(app.config['UPLOAD_FOLDER'], filename))
  File "/usr/local/lib/python2.7/dist-packages/werkzeug/datastructures.py", line 2725, in save
    dst = open(dst, 'wb')
IOError: [Errno 2] No such file or directory: './upload/../air1.jpg'
2018-02-22 14:23:20,122 INFO: Blog startup [in /home/broccoli/161220049_web_programming/blog/app/__init__.py:44]
