2018-02-22 12:57:09,918 INFO: Blog startup [in /home/broccoli/161220049_web_programming/blog/app/__init__.py:44]
2018-02-22 12:59:40,492 INFO: Blog startup [in /home/broccoli/161220049_web_programming/blog/app/__init__.py:44]
2018-02-22 12:59:44,217 ERROR: Exception on /post/3 [POST] [in /usr/local/lib/python2.7/dist-packages/flask/app.py:1560]
Traceback (most recent call last):
  File "/usr/local/lib/python2.7/dist-packages/flask/app.py", line 1982, in wsgi_app
    response = self.full_dispatch_request()
  File "/usr/local/lib/python2.7/dist-packages/flask/app.py", line 1614, in full_dispatch_request
    rv = self.handle_user_exception(e)
  File "/usr/local/lib/python2.7/dist-packages/flask/app.py", line 1517, in handle_user_exception
    reraise(exc_type, exc_value, tb)
  File "/usr/local/lib/python2.7/dist-packages/flask/app.py", line 1612, in full_dispatch_request
    rv = self.dispatch_request()
  File "/usr/local/lib/python2.7/dist-packages/flask/app.py", line 1598, in dispatch_request
    return self.view_functions[rule.endpoint](**req.view_args)
  File "/usr/local/lib/python2.7/dist-packages/flask_login/utils.py", line 261, in decorated_view
    return func(*args, **kwargs)
  File "/home/broccoli/161220049_web_programming/blog/app/routes.py", line 99, in post
    comment = Comment(body = form.body.data, post=post, author=current_user)
AttributeError: 'CommentForm' object has no attribute 'body'
2018-02-22 13:00:45,893 INFO: Blog startup [in /home/broccoli/161220049_web_programming/blog/app/__init__.py:44]
2018-02-22 13:18:35,026 INFO: Blog startup [in /home/broccoli/161220049_web_programming/blog/app/__init__.py:44]
2018-02-22 13:28:49,295 INFO: Blog startup [in /home/broccoli/161220049_web_programming/blog/app/__init__.py:44]
2018-02-22 13:29:46,119 ERROR: Exception on /upload_file [POST] [in /usr/local/lib/python2.7/dist-packages/flask/app.py:1560]
Traceback (most recent call last):
  File "/usr/local/lib/python2.7/dist-packages/flask/app.py", line 1982, in wsgi_app
    response = self.full_dispatch_request()
  File "/usr/local/lib/python2.7/dist-packages/flask/app.py", line 1614, in full_dispatch_request
    rv = self.handle_user_exception(e)
  File "/usr/local/lib/python2.7/dist-packages/flask/app.py", line 1517, in handle_user_exception
    reraise(exc_type, exc_value, tb)
  File "/usr/local/lib/python2.7/dist-packages/flask/app.py", line 1612, in full_dispatch_request
    rv = self.dispatch_request()
  File "/usr/local/lib/python2.7/dist-packages/flask/app.py", line 1598, in dispatch_request
    return self.view_functions[rule.endpoint](**req.view_args)
  File "/usr/local/lib/python2.7/dist-packages/flask_login/utils.py", line 261, in decorated_view
    return func(*args, **kwargs)
  File "/home/broccoli/161220049_web_programming/blog/app/routes.py", line 223, in upload_file
    filename = secure_filename(file.filename)
NameError: global name 'secure_filename' is not defined
2018-02-22 13:31:54,568 INFO: Blog startup [in /home/broccoli/161220049_web_programming/blog/app/__init__.py:44]
2018-02-22 13:32:41,415 ERROR: Exception on /upload_file [POST] [in /usr/local/lib/python2.7/dist-packages/flask/app.py:1560]
Traceback (most recent call last):
  File "/usr/local/lib/python2.7/dist-packages/flask/app.py", line 1982, in wsgi_app
    response = self.full_dispatch_request()
  File "/usr/local/lib/python2.7/dist-packages/flask/app.py", line 1614, in full_dispatch_request
    rv = self.handle_user_exception(e)
  File "/usr/local/lib/python2.7/dist-packages/flask/app.py", line 1517, in handle_user_exception
    reraise(exc_type, exc_value, tb)
  File "/usr/local/lib/python2.7/dist-packages/flask/app.py", line 1612, in full_dispatch_request
    rv = self.dispatch_request()
  File "/usr/local/lib/python2.7/dist-packages/flask/app.py", line 1598, in dispatch_request
    return self.view_functions[rule.endpoint](**req.view_args)
  File "/usr/local/lib/python2.7/dist-packages/flask_login/utils.py", line 261, in decorated_view
    return func(*args, **kwargs)
  File "/home/broccoli/161220049_web_programming/blog/app/routes.py", line 225, in upload_file
    file.save(os.path.join(UPLOAD_FOLDER, filename))
NameError: global name 'os' is not defined
2018-02-22 13:33:01,746 INFO: Blog startup [in /home/broccoli/161220049_web_programming/blog/app/__init__.py:44]
2018-02-22 13:33:29,316 ERROR: Exception on /upload_file [POST] [in /usr/local/lib/python2.7/dist-packages/flask/app.py:1560]
Traceback (most recent call last):
  File "/usr/local/lib/python2.7/dist-packages/flask/app.py", line 1982, in wsgi_app
    response = self.full_dispatch_request()
  File "/usr/local/lib/python2.7/dist-packages/flask/app.py", line 1614, in full_dispatch_request
    rv = self.handle_user_exception(e)
  File "/usr/local/lib/python2.7/dist-packages/flask/app.py", line 1517, in handle_user_exception
    reraise(exc_type, exc_value, tb)
  File "/usr/local/lib/python2.7/dist-packages/flask/app.py", line 1612, in full_dispatch_request
    rv = self.dispatch_request()
  File "/usr/local/lib/python2.7/dist-packages/flask/app.py", line 1598, in dispatch_request
    return self.view_functions[rule.endpoint](**req.view_args)
  File "/usr/local/lib/python2.7/dist-packages/flask_login/utils.py", line 261, in decorated_view
    return func(*args, **kwargs)
  File "/home/broccoli/161220049_web_programming/blog/app/routes.py", line 226, in upload_file
    file.save(os.path.join(UPLOAD_FOLDER, filename))
  File "/usr/local/lib/python2.7/dist-packages/werkzeug/datastructures.py", line 2725, in save
    dst = open(dst, 'wb')
IOError: [Errno 2] No such file or directory: 'upload/Screenshot_from_2017-09-21_18-51-47.png'
2018-02-22 13:48:59,952 INFO: Blog startup [in /home/broccoli/161220049_web_programming/blog/app/__init__.py:44]
2018-02-22 13:49:29,219 ERROR: Exception on /upload_file [POST] [in /usr/local/lib/python2.7/dist-packages/flask/app.py:1560]
Traceback (most recent call last):
  File "/usr/local/lib/python2.7/dist-packages/flask/app.py", line 1982, in wsgi_app
    response = self.full_dispatch_request()
  File "/usr/local/lib/python2.7/dist-packages/flask/app.py", line 1614, in full_dispatch_request
    rv = self.handle_user_exception(e)
  File "/usr/local/lib/python2.7/dist-packages/flask/app.py", line 1517, in handle_user_exception
    reraise(exc_type, exc_value, tb)
  File "/usr/local/lib/python2.7/dist-packages/flask/app.py", line 1612, in full_dispatch_request
    rv = self.dispatch_request()
  File "/usr/local/lib/python2.7/dist-packages/flask/app.py", line 1598, in dispatch_request
    return self.view_functions[rule.endpoint](**req.view_args)
  File "/usr/local/lib/python2.7/dist-packages/flask_login/utils.py", line 261, in decorated_view
    return func(*args, **kwargs)
  File "/home/broccoli/161220049_web_programming/blog/app/routes.py", line 223, in upload_file
    file.save(os.path.join(app.config['UPLOAD_FOLDER'], filename))
  File "/usr/local/lib/python2.7/dist-packages/werkzeug/datastructures.py", line 2725, in save
    dst = open(dst, 'wb')
IOError: [Errno 2] No such file or directory: '/upload/air1.jpg'
2018-02-22 13:50:42,129 INFO: Blog startup [in /home/broccoli/161220049_web_programming/blog/app/__init__.py:44]
2018-02-22 13:50:57,149 ERROR: Exception on /upload_file [POST] [in /usr/local/lib/python2.7/dist-packages/flask/app.py:1560]
Traceback (most recent call last):
  File "/usr/local/lib/python2.7/dist-packages/flask/app.py", line 1982, in wsgi_app
    response = self.full_dispatch_request()
  File "/usr/local/lib/python2.7/dist-packages/flask/app.py", line 1614, in full_dispatch_request
    rv = self.handle_user_exception(e)
  File "/usr/local/lib/python2.7/dist-packages/flask/app.py", line 1517, in handle_user_exception
    reraise(exc_type, exc_value, tb)
  File "/usr/local/lib/python2.7/dist-packages/flask/app.py", line 1612, in full_dispatch_request
    rv = self.dispatch_request()
  File "/usr/local/lib/python2.7/dist-packages/flask/app.py", line 1598, in dispatch_request
    return self.view_functions[rule.endpoint](**req.view_args)
  File "/usr/local/lib/python2.7/dist-packages/flask_login/utils.py", line 261, in decorated_view
    return func(*args, **kwargs)
  File "/home/broccoli/161220049_web_programming/blog/app/routes.py", line 223, in upload_file
    file.save(os.path.join(app.config['UPLOAD_FOLDER'], filename))
  File "/usr/local/lib/python2.7/dist-packages/werkzeug/datastructures.py", line 2725, in save
    dst = open(dst, 'wb')
IOError: [Errno 2] No such file or directory: '/app/upload/air1.jpg'
2018-02-22 13:51:36,248 INFO: Blog startup [in /home/broccoli/161220049_web_programming/blog/app/__init__.py:44]
2018-02-22 13:51:52,601 ERROR: Exception on /upload_file [POST] [in /usr/local/lib/python2.7/dist-packages/flask/app.py:1560]
Traceback (most recent call last):
  File "/usr/local/lib/python2.7/dist-packages/flask/app.py", line 1982, in wsgi_app
    response = self.full_dispatch_request()
  File "/usr/local/lib/python2.7/dist-packages/flask/app.py", line 1614, in full_dispatch_request
    rv = self.handle_user_exception(e)
  File "/usr/local/lib/python2.7/dist-packages/flask/app.py", line 1517, in handle_user_exception
    reraise(exc_type, exc_value, tb)
  File "/usr/local/lib/python2.7/dist-packages/flask/app.py", line 1612, in full_dispatch_request
    rv = self.dispatch_request()
  File "/usr/local/lib/python2.7/dist-packages/flask/app.py", line 1598, in dispatch_request
    return self.view_functions[rule.endpoint](**req.view_args)
  File "/usr/local/lib/python2.7/dist-packages/flask_login/utils.py", line 261, in decorated_view
    return func(*args, **kwargs)
  File "/home/broccoli/161220049_web_programming/blog/app/routes.py", line 223, in upload_file
    file.save(os.path.join(app.config['UPLOAD_FOLDER'], filename))
  File "/usr/local/lib/python2.7/dist-packages/werkzeug/datastructures.py", line 2725, in save
    dst = open(dst, 'wb')
IOError: [Errno 2] No such file or directory: '/../upload/air1.jpg'
2018-02-22 14:01:48,384 INFO: Blog startup [in /home/broccoli/161220049_web_programming/blog/app/__init__.py:44]
